Workbook
Name Slicer_INVESTIGATION_TYPE: #N/A
Name Slicer_INVESTIGATOR: #N/A
Name Slicer_MONTH: #N/A
Name Slicer_REGION: #N/A

Sheet RawData
A1: CASE_Id | B1: DATE | C1: MONTH | D1: WEEK | E1: QUARTER | F1: INVESTIGATOR | G1: INVESTIGATION_TYPE | H1: QUEUE | I1: REGION | J1: PRIORITY | K1: CASE_HANDLED | L1: DECISION | M1: SLA | N1: STATUS | O1: HANDLE_TIME | P1: INVESTIGATION_RESULT | Q1: QUALITY_SCORE | T1: INVESTIGATOR | U1: INVESTIGATION_TYPE | V1: REGION | W1: PRIORITY | X1: DECISION | Y1: SLA | Z1: STATUS | AA1: INVESTIGATION_RESULT | AB1: QUEUE
A2: ="NOI"&TEXT(ROW()-1,"000000") -> NOI000001 | B2: 45819 | C2: June | D2: 24 | E2: Q2 | F2: Pooja Patel | G2: Copyright | H2: NOI Reports | I2: Japan | J2: Medium | K2: 1 | L2: Enforced | M2: Met | N2: Closed | O2: 7 | P2: Valid | Q2: 0.95 | T2: Riya Chakravarty | U2: Trademark | V2: USA | W2: High | X2: Enforced | Y2: Met | Z2: Closed | AA2: Valid | AB2: NOI Reports
A3: ="NOI"&TEXT(ROW()-1,"000000") -> NOI000002 | B3: 45732 | C3: March | D3: 12 | E3: Q1 | F3: Neha Singh | G3: Patent | H3: NOI Reports | I3: Canada | J3: High | K3: 1 | L3: Rejected | M3: Met | N3: Closed | O3: 9 | P3: Valid | Q3: 0.99 | T3: Priya Mishra | U3: Counterfeit | V3: India | W3: Medium | X3: Rejected | Y3: Breached | Z3: Open | AA3: Invalid | AB3: NOI Appeals
A4: ="NOI"&TEXT(ROW()-1,"000000") -> NOI000003 | B4: 45933 | C4: October | D4: 40 | E4: Q4 | F4: Megha Bose | G4: Counterfeit | H4: NOI Reports | I4: UK | J4: High | K4: 1 | L4: Enforced | M4: Met | N4: Closed | O4: 9 | P4: Valid | Q4: 0.97 | T4: Akash Sandhu | U4: Copyright | V4: UK | W4: Low | X4: Reinstated
A5: ="NOI"&TEXT(ROW()-1,"000000") -> NOI000004 | B5: 45954 | C5: October | D5: 43 | E5: Q4 | F5: Rahul Sharma | G5: Design | H5: NOI Reports | I5: Singapore | J5: Medium | K5: 1 | L5: Enforced | M5: Met | N5: Closed | O5: 8 | P5: Valid | Q5: 0.99 | T5: Harshad Choudhury | U5: Design | V5: Canada
A6: ="NOI"&TEXT(ROW()-1,"000000") -> NOI000005 | B6: 45675 | C6: January | D6: 3 | E6: Q1 | F6: Sneha Gupta | G6: Counterfeit | H6: NOI Appeals | I6: Canada | J6: Medium | K6: 1 | L6: Enforced | M6: Met | N6: Closed | O6: 9 | P6: Valid | Q6: 0.99 | T6: Ankit Verma | U6: Patent | V6: Germany
A7: ="NOI"&TEXT(ROW()-1,"000000") -> NOI000006 | B7: 45752 | C7: April | D7: 14 | E7: Q2 | F7: Megha Bose | G7: Patent | H7: NOI Reports | I7: Germany | J7: Medium | K7: 1 | L7: Enforced | M7: Met | N7: Closed | O7: 10 | P7: Valid | Q7: 0.96 | T7: Sneha Gupta | V7: Australia
A8: ="NOI"&TEXT(ROW()-1,"000000") -> NOI000007 | B8: 45726 | C8: March | D8: 11 | E8: Q1 | F8: Ankit Verma | G8: Design | H8: NOI Appeals | I8: USA | J8: Medium | K8: 1 | L8: Rejected | M8: Met | N8: Closed | O8: 10 | P8: Valid | Q8: 0.99 | T8: Rahul Sharma | V8: Singapore
A9: ="NOI"&TEXT(ROW()-1,"000000") -> NOI000008 | B9: 45805 | C9: May | D9: 22 | E9: Q2 | F9: Aditi Roy | G9: Design | H9: NOI Reports | I9: Singapore | J9: High | K9: 1 | L9: Rejected | M9: Met | N9: Closed | O9: 9 | P9: Valid | Q9: 0.94 | T9: Aditi Roy | V9: Japan
A10: ="NOI"&TEXT(ROW()-1,"000000") -> NOI000009 | B10: 45951 | C10: October | D10: 43 | E10: Q4 | F10: Pooja Patel | G10: Copyright | H10: NOI Appeals | I10: India | J10: High | K10: 1 | L10: Enforced | M10: Met | N10: Closed | O10: 9 | P10: Valid | Q10: 0.94 | T10: Sourav Das
A11: ="NOI"&TEXT(ROW()-1,"000000") -> NOI000010 | B11: 45849 | C11: July | D11: 28 | E11: Q3 | F11: Megha Bose | G11: Design | H11: NOI Appeals | I11: Australia | J11: High | K11: 1 | L11: Rejected | M11: Met | N11: Closed | O11: 9 | P11: Valid | Q11: 0.98 | T11: Neha Singh
A12: ="NOI"&TEXT(ROW()-1,"000000") -> NOI000011 | B12: 45833 | C12: June | D12: 26 | E12: Q2 | F12: Abhishek Roy | G12: Trademark | H12: NOI Appeals | I12: Germany | J12: Medium | K12: 1 | L12: Enforced | M12: Met | N12: Closed | O12: 7 | P12: Valid | Q12: 0.94 | T12: Arjun Nair
A13: ="NOI"&TEXT(ROW()-1,"000000") -> NOI000012 | B13: 45764 | C13: April | D13: 16 | E13: Q2 | F13: Priya Mishra | G13: Counterfeit | H13: NOI Reports | I13: Canada | J13: Medium | K13: 1 | L13: Enforced | M13: Met | N13: Closed | O13: 7 | P13: Invalid | Q13: 0.94 | T13: Karan Mehta
A14: ="NOI"&TEXT(ROW()-1,"000000") -> NOI000013 | B14: 45996 | C14: December | D14: 49 | E14: Q4 | F14: Sourav Das | G14: Copyright | H14: NOI Appeals | I14: UK | J14: Medium | K14: 1 | L14: Rejected | M14: Met | N14: Closed | O14: 8 | P14: Valid | Q14: 0.99 | T14: Pooja Patel
A15: ="NOI"&TEXT(ROW()-1,"000000") -> NOI000014 | B15: 45723 | C15: March | D15: 10 | E15: Q1 | F15: Harshad Choudhury | G15: Trademark | H15: NOI Appeals | I15: USA | J15: High | K15: 1 | L15: Enforced | M15: Met | N15: Closed | O15: 10 | P15: Valid | Q15: 0.97 | T15: Vikram Joshi
A16: ="NOI"&TEXT(ROW()-1,"000000") -> NOI000015 | B16: 45751 | C16: April | D16: 14 | E16: Q2 | F16: Vikram Joshi | G16: Counterfeit | H16: NOI Appeals | I16: UK | J16: High | K16: 1 | L16: Enforced | M16: Met | N16: Closed | O16: 8 | P16: Valid | Q16: 0.95 | T16: Ananya Sen
A17: ="NOI"&TEXT(ROW()-1,"000000") -> NOI000016 | B17: 45924 | C17: September | D17: 39 | E17: Q3 | F17: Harshad Choudhury | G17: Copyright | H17: NOI Appeals | I17: India | J17: Medium | K17: 1 | L17: Rejected | M17: Met | N17: Closed | O17: 6 | P17: Valid | Q17: 0.94 | T17: Rohit Kumar
A18: ="NOI"&TEXT(ROW()-1,"000000") -> NOI000017 | B18: 45953 | C18: October | D18: 43 | E18: Q4 | F18: Rahul Sharma | G18: Patent | H18: NOI Reports | I18: India | J18: Medium | K18: 1 | L18: Rejected | M18: Breached | N18: Closed | O18: 6 | P18: Valid | Q18: 0.96 | T18: Megha Bose
A19: ="NOI"&TEXT(ROW()-1,"000000") -> NOI000018 | B19: 45682 | C19: January | D19: 4 | E19: Q1 | F19: Vikram Joshi | G19: Counterfeit | H19: NOI Reports | I19: India | J19: Medium | K19: 1 | L19: Rejected | M19: Met | N19: Closed | O19: 9 | P19: Valid | Q19: 0.97 | T19: Abhishek Roy
A20: ="NOI"&TEXT(ROW()-1,"000000") -> NOI000019 | B20: 45969 | C20: November | D20: 45 | E20: Q4 | F20: Karan Mehta | G20: Design | H20: NOI Appeals | I20: India | J20: Medium | K20: 1 | L20: Rejected | M20: Met | N20: Closed | O20: 6 | P20: Valid | Q20: 0.98 | T20: Simran Kaur
A21: ="NOI"&TEXT(ROW()-1,"000000") -> NOI000020 | B21: 45844 | C21: July | D21: 28 | E21: Q3 | F21: Rohit Kumar | G21: Patent | H21: NOI Reports | I21: Australia | J21: High | K21: 1 | L21: Rejected | M21: Met | N21: Closed | O21: 8 | P21: Valid | Q21: 0.99 | T21: Aman Gupta
A22: ="NOI"&TEXT(ROW()-1,"000000") -> NOI000021 | B22: 45826 | C22: June | D22: 25 | E22: Q2 | F22: Riya Chakravarty | G22: Design | H22: NOI Reports | I22: UK | J22: Medium | K22: 1 | L22: Rejected | M22: Met | N22: Closed | O22: 10 | P22: Valid | Q22: 0.98
A23: ="NOI"&TEXT(ROW()-1,"000000") -> NOI000022 | B23: 45734 | C23: March | D23: 12 | E23: Q1 | F23: Aditi Roy | G23: Patent | H23: NOI Reports | I23: Australia | J23: High | K23: 1 | L23: Rejected | M23: Met | N23: Open | O23: 10 | P23: Valid | Q23: 0.95
A24: ="NOI"&TEXT(ROW()-1,"000000") -> NOI000023 | B24: 45659 | C24: January | D24: 1 | E24: Q1 | F24: Akash Sandhu | G24: Design | H24: NOI Appeals | I24: UK | J24: Medium | K24: 1 | L24: Rejected | M24: Met | N24: Closed | O24: 9 | P24: Valid | Q24: 0.96
A25: ="NOI"&TEXT(ROW()-1,"000000") -> NOI000024 | B25: 45937 | C25: October | D25: 41 | E25: Q4 | F25: Neha Singh | G25: Trademark | H25: NOI Appeals | I25: UK | J25: Medium | K25: 1 | L25: Enforced | M25: Met | N25: Closed | O25: 10 | P25: Valid | Q25: 0.96
A26: ="NOI"&TEXT(ROW()-1,"000000") -> NOI000025 | B26: 45860 | C26: July | D26: 30 | E26: Q3 | F26: Sourav Das | G26: Design | H26: NOI Reports | I26: Japan | J26: High | K26: 1 | L26: Rejected | M26: Met | N26: Closed | O26: 10 | P26: Valid | Q26: 0.94
A27: ="NOI"&TEXT(ROW()-1,"000000") -> NOI000026 | B27: 45730 | C27: March | D27: 11 | E27: Q1 | F27: Karan Mehta | G27: Patent | H27: NOI Reports | I27: UK | J27: High | K27: 1 | L27: Enforced | M27: Met | N27: Closed | O27: 8 | P27: Valid | Q27: 0.99
A28: ="NOI"&TEXT(ROW()-1,"000000") -> NOI000027 | B28: 45901 | C28: September | D28: 36 | E28: Q3 | F28: Priya Mishra | G28: Design | H28: NOI Reports | I28: Canada | J28: Medium | K28: 1 | L28: Rejected | M28: Met | N28: Closed | O28: 6 | P28: Valid | Q28: 0.96
A29: ="NOI"&TEXT(ROW()-1,"000000") -> NOI000028 | B29: 45833 | C29: June | D29: 26 | E29: Q2 | F29: Simran Kaur | G29: Copyright | H29: NOI Reports | I29: India | J29: High | K29: 1 | L29: Rejected | M29: Met | N29: Closed | O29: 8 | P29: Valid | Q29: 0.98
A30: ="NOI"&TEXT(ROW()-1,"000000") -> NOI000029 | B30: 45970 | C30: November | D30: 46 | E30: Q4 | F30: Aditi Roy | G30: Copyright | H30: NOI Reports | I30: UK | J30: High | K30: 1 | L30: Enforced | M30: Met | N30: Open | O30: 8 | P30: Valid | Q30: 0.94
A31: ="NOI"&TEXT(ROW()-1,"000000") -> NOI000030 | B31: 45856 | C31: July | D31: 29 | E31: Q3 | F31: Karan Mehta | G31: Copyright | H31: NOI Reports | I31: UK | J31: High | K31: 1 | L31: Rejected | M31: Met | N31: Closed | O31: 8 | P31: Valid | Q31: 0.96
A32: ="NOI"&TEXT(ROW()-1,"000000") -> NOI000031 | B32: 45671 | C32: January | D32: 3 | E32: Q1 | F32: Ananya Sen | G32: Counterfeit | H32: NOI Reports | I32: Australia | J32: High | K32: 1 | L32: Rejected | M32: Met | N32: Closed | O32: 10 | P32: Valid | Q32: 0.99
A33: ="NOI"&TEXT(ROW()-1,"000000") -> NOI000032 | B33: 45753 | C33: April | D33: 15 | E33: Q2 | F33: Priya Mishra | G33: Counterfeit | H33: NOI Appeals | I33: UK | J33: Medium | K33: 1 | L33: Rejected | M33: Breached | N33: Closed | O33: 10 | P33: Valid | Q33: 0.96
... A501: ="NOI"&TEXT(ROW()-1,"000000") -> NOI000500 | B501: 45700 | C501: February | D501: 7 | E501: Q1 | F501: Ananya Sen | G501: Counterfeit | H501: NOI Reports | I501: USA | J501: High | K501: 1 | L501: Enforced | M501: Met | N501: Closed | O501: 10 | P501: Invalid | Q501: 0.96

Sheet Dashboard
C1: Investigation Operations Performance Dashboard
C15: Total Cases | E15: =GETPIVOTDATA("CASE_HANDLED",PivotData!$E$9) -> 500 | F15: Average Quality | H15: =GETPIVOTDATA("QUALITY_SCORE",PivotData!$E$1) -> 0.96558 | I15: SLA Met % | K15: =PivotData!G31 -> 0.948 | L15: Avg Resolution Time | N15: =GETPIVOTDATA("HANDLE_TIME",PivotData!$E$36) -> 8.042 | O15: Investigator | Q15: =PivotData!A36 -> Simran Kaur
D59: Created using Microsoft Excel | PivotTables | PivotCharts | Slicers | Interactive Dashboard

Sheet PivotData
A1: Row Labels | B1: Sum of CASE_HANDLED | E1: Average of QUALITY_SCORE
A2: Copyright | B2: 96 | E2: 0.96558
A3: Counterfeit | B3: 112
A4: Design | B4: 102
A5: Patent | B5: 89
A6: Trademark | B6: 101
A7: Grand Total | B7: 500
E9: Sum of CASE_HANDLED
E10: 500
A15: Row Labels | B15: Sum of CASE_HANDLED | E15: Count of INVESTIGATOR
A16: January | B16: 40 | E16: 500
A17: February | B17: 42
A18: March | B18: 29
A19: April | B19: 59
A20: May | B20: 45
A21: June | B21: 37
A22: July | B22: 42
A23: August | B23: 41 | E23: Average of CASE_HANDLED
A24: September | B24: 51 | E24: 1
A25: October | B25: 43
A26: November | B26: 37
A27: December | B27: 34
A28: Grand Total | B28: 500 | C28: =GETPIVOTDATA("CASE_HANDLED",$A$15)/(31*10) -> 1.6129032
E29: Row Labels | F29: Sum of CASE_HANDLED
E30: Breached | F30: 26
E31: Met | F31: 474 | G31: =GETPIVOTDATA("CASE_HANDLED",$E$29,"SLA","Met")/GETPIVOTDATA("CASE_HANDLED",$E$29) -> 0.948
E32: Grand Total | F32: 500
A35: Row Labels | B35: Sum of CASE_HANDLED
A36: Simran Kaur | B36: 37 | E36: Average of HANDLE_TIME
A37: Aditi Roy | B37: 34 | E37: 8.042
A38: Akash Sandhu | B38: 30
A39: Ananya Sen | B39: 29
A40: Karan Mehta | B40: 29
A41: Priya Mishra | B41: 28
A42: Aman Gupta | B42: 28
A43: Neha Singh | B43: 28
A44: Sneha Gupta | B44: 25
A45: Arjun Nair | B45: 25
A46: Sourav Das | B46: 24
A47: Vikram Joshi | B47: 24
...
